Workbook

Sheet Fields&Module
A1: 0 | B1: 0 | D1: LIFE | H1: GENERAL | L1: Y/N | M1: Freq | N1: MOP | O1: TableName > | P1: Policy | Q1: Schedule | R1: PayPlan | S1: Debit Notes | T1: Payments | U1: Vehicles | V1: Nominee | W1: ComNotes | X1: ComPay | Y1: Statement | Z1: Endorsements | AA1: R-Notices | AB1: Client | AC1: BO | AD1: Contact | AE1: FU | AF1: Proposals | AG1: Tasks | AH1: Claims | AI1: Income | AJ1: Expenses | AK1: Tax
A2: 1 | B2: 0 | H2: Field Name | I2: =SUM(I3:I201) -> 0 | J2: Field Type | K2: Default | L2: =SUM(L32:L292) -> 3 | M2: =SUM(M32:M292) -> 4 | N2: =SUM(N32:N292) -> 2 | O2: No Of Fields > | P2: =SUM(P3:P307) -> 19 | Q2: =SUM(Q3:Q307) -> 14 | R2: =SUM(R3:R307) -> 9 | S2: =SUM(S3:S307) -> 5 | T2: =SUM(T3:T307) -> 11 | U2: =SUM(U3:U307) -> 19 | V2: =SUM(V3:V307) -> 11 | W2: =SUM(W3:W307) -> 6 | ... AK2: =SUM(AK3:AK307) -> 16 | AL2: =SUM(P2:AK2) -> 289
A3: 1 | B3: 1 | C3: Policy | D3: PolicyID | H3: PolicyID | J3: UniqueID | P3: 1
A4: 2 | B4: 2 | C4: Policy | D4: ClientID | H4: ClientID | J4: Unique ID | P4: 1
A5: 3 | B5: 3 | C5: Policy | D5: Policy No | H5: Policy No | J5: UniqueNo | P5: 1
A6: 4 | B6: 4 | C6: Policy | D6: Insurer | H6: Insurer | J6: LookUp Table | P6: 1
A7: 5 | B7: 5 | C7: Policy | D7: Class | H7: Class | J7: LookUp Table | P7: 1
A8: 6 | B8: 6 | C8: Policy | H8: Insured | J8: Text | P8: 1
A9: 6 | B9: 6 | C9: Policy | D9: Policy Type | J9: LookUp Table | P9: 1
A10: 7 | B10: 7 | C10: Policy | D10: Application Date | H10: Application Date | J10: Date | K10: [Today] | P10: 1
A11: 8 | B11: 8 | C11: Policy | D11: Business | H11: Business | J11: LookUp Table | K11: Direct | P11: 1
A12: 9 | B12: 9 | C12: Policy | D12: PolicyStatus | H12: PolicyStatus | J12: Derived | K12: In Force | P12: 1
A13: 10 | B13: 10 | C13: Policy | D13: RenewalNotices | H13: RenewalNotices | J13: Check Box | P13: 1
A14: 11 | B14: 11 | C14: Policy | D14: Channel | H14: Channel | J14: LookUp Table | P14: 1
A15: 12 | B15: 12 | C15: Policy | D15: DFR | H15: DFR | J15: Highlight | K15: Off | L15: 1 | P15: 1
A16: 13 | B16: 13 | C16: Policy | D16: Agency | H16: Agency | J16: LookUp Table | K16: Keystone | P16: 1
A17: 14 | B17: 14 | C17: Policy | D17: Agent | H17: Agent | J17: Text | K17: Mandy | P17: 1
A18: 15 | B18: 15 | C18: Policy | D18: Source | H18: Source | J18: LookUp Table | P18: 1
A19: 16 | B19: 16 | C19: Policy | D19: Source Name | H19: Source Name | J19: Text | P19: 1
A20: 17 | B20: 17 | C20: Policy | D20: Notes | H20: Notes | J20: Text | P20: 1
A21: 18 | B21: 18 | C21: Policy | D21: [Documents] | H21: [Documents] | J21: Attachment | P21: 1
A22: 19 | B22: 1 | C22: Schedule | D22: ScheduleID | H22: ScheduleID | J22: Unique ID | Q22: 1
A23: 20 | B23: 2 | C23: Schedule | D23: PolicyID | H23: PolicyID | J23: Unique ID | Q23: 1
A24: 21 | B24: 3 | C24: Schedule | D24: Year | H24: Year | J24: Numbers | K24: [Current] | Q24: 1
A25: 22 | B25: 4 | C25: Schedule | D25: Plan | H25: Plan | J25: Text | Q25: 1
A26: 23 | B26: 5 | C26: Schedule | D26: Sum Assured | H26: SumInsured | J26: Currency | Q26: 1
A27: 25 | B27: 7 | C27: Schedule | D27: Term [No] | H27: Term [No] | J27: Numbers | K27: 1 | Q27: 1
A28: 26 | B28: 8 | C28: Schedule | D28: Term [Period] | H28: Term [Period] | J28: LookUp Table | K28: Year | Q28: 1
A29: 27 | B29: 9 | C29: Schedule | D29: StartDate | H29: StartDate | J29: Date | K29: [Today] | Q29: 1
A30: 28 | B30: 10 | C30: Schedule | D30: End Date | H30: End Date | J30: Date | K30: Calculated | Q30: 1
A31: 29 | B31: 11 | C31: Schedule | D31: Cancelled Date | H31: Cancelled Date | J31: Date | Q31: 1
A32: 30 | B32: 12 | C32: Schedule | D32: AddONs | H32: AddONs | J32: Text | Q32: 1
A33: 31 | B33: 13 | C33: Schedule | D33: BasePremium | H33: BasePremium | J33: Currency | Q33: 1
A34: 32 | B34: 14 | C34: Schedule | D34: TotalPremium | H34: TotalPremium | J34: Currency | Q34: 1
A35: 33 | B35: 15 | C35: Schedule | D35: [Documents] | H35: [Documents] | J35: Attachment | M35: 1 | Q35: 1
A36: 35 | B36: 1 | C36: PayPlan | D36: PayPlanID | H36: PayPlanID | J36: Unique ID | R36: 1
A37: 36 | B37: 2 | C37: PayPlan | D37: ScheduleID | H37: ScheduleID | J37: Unique ID | R37: 1
A38: 37 | B38: 3 | C38: PayPlan | D38: PaymentPlan | H38: PaymentPlan | J38: LookUp Table | K38: Single | R38: 1
A39: 38 | B39: 4 | C39: PayPlan | D39: No Of Instalments | H39: No Of Instalments | J39: Numbers | K39: 1 | R39: 1
A40: 39 | B40: 5 | C40: PayPlan | D40: Frequency | H40: Frequency | J40: LookUp Table | R40: 1
...

Sheet Login

Sheet Template

Sheet System DB
B2: CLIENTS | E2: POLICIES MANAGEMENT | T2: PREMIUM PAYMENTS MANAGEMENT | AF2: LEADS & LIFE INSURANCE
AB4: PAYMENTS | AJ4: PROPOSALS
X5: DEBIT NOTES | AB5: PaymentID | AF5: CONTACTS | AJ5: PRID | AK5: 1
T6: PAYMENTPLAN | X6: DebitNoteID | Y6: 1 | AA6: M | AB6: =X6 -> DebitNoteID | AF6: ContactID | AG6: 1 | AI6: M | AJ6: =AF6 -> ContactID
P7: SCHEDULES | T7: PayPlanID | U7: 1 | W7: M | X7: =T7 -> PayPlanID
E8: POLICIES | P8: ScheduleID | Q8: 1 | S8: M | T8: =P8 -> ScheduleID
B9: CLIENTS | E9: PolicyID | F9: 1 | O9: M | P9: =E9 -> PolicyID | AJ9: MEDICALS
B10: Client ID | C10: 1 | D10: M | E10: =B10 -> Client ID | P10: Attachments | AF10: FOLLOWUPS | AJ10: MedID
B11: ClientType* | E11: PolicyNO | L11: RENEWALNotices | P11: DebitNote | AF11: FUID | AJ11: =AJ5 -> PRID | AK11: 1
B12: Name | L12: RNID | P12: Receipt | AF12: =AF6 -> ContactID | AG12: M
E13: Attachments | K13: M | L13: =E9 -> PolicyID | P13: PolicySchedule | T13: COMMISSION MANAGEMENT | AF13: =B10 -> Client ID
B14: Attachments | E14: Proposal Form | P14: RenewalNotice | AF14: =AJ5 -> PRID
B15: ID | E15: Vehicle RC | P15: Payment Agreement
B16: POA | E16: Quotes | X16: COMMISSIONS
B17: BusinessDocs | E17: QS Reports | L17: VEHICLES | T17: Com NOTE | X17: ComID
E18: Photos | L18: VehicleID | T18: ComNoteID | U18: 1 | W18: M | X18: =T18 -> ComNoteID | AB18: COMStatement | AF18: FINANCIAL MANAGEMENT
L19: =E9 -> PolicyID | S19: 1 | T19: =P8 -> ScheduleID | X19: =AB19 -> ComStatID | Y19: M | AA19: 1 | AB19: ComStatID | AC19: 1
E20: CLAIMS | L20: RegnNo | AB20: Attachments
B21: BeneficialOwners | E21: ClaimID | AB21: ComStat | AF21: INCOME | AJ21: TAX RETURN
B22: BOID | E22: =E9 -> PolicyID | F22: M | L22: Attachments | AF22: IncomeID | AJ22: TaxRetID
B23: =B10 -> Client ID | C23: M | E23: Attachments | L23: SLTA Certificate | AE23: 1 | AF23: =AB19 -> ComStatID
B24: Name | E24: ClaimForm | L24: Proof Of Purchase | AF24: Attachments
E25: Other Docs | L25: Value Certificate | T25: OTHER MODULES | AF25: Bank Statements
B26: Attachments
B27: ID | E27: NOMINEES | L27: ENDORSEMENTS
B28: POA | E28: NomineeID | L28: EndorseID | T28: SYSTEM | X28: DOCUMENTS | AB28: NOTIFICATIONS | AF28: EXPENSES
E29: =E9 -> PolicyID | F29: M | L29: =E9 -> PolicyID | AF29: ExpensesID
E30: Name | AF30: Attachments
E31: Attachments | AF31: Receipts
E32: IDS | T32: CALENDAR | X32: REPORTS | AB32: TASKS

Sheet P1
E2: POLICIES MANAGEMENT | T2: PREMIUM PAYMENTS MANAGEMENT
AB4: PAYMENTS
X5: DEBIT NOTES | AB5: PaymentID
T6: PAYMENTPLAN | X6: DebitNoteID | Y6: 1 | AA6: M | AB6: =X6 -> DebitNoteID
P7: SCHEDULES | T7: PayPlanID | U7: 1 | W7: M | X7: =T7 -> PayPlanID
E8: POLICIES | P8: ScheduleID | Q8: 1 | S8: M | T8: =P8 -> ScheduleID
E9: PolicyID | F9: 1 | O9: M | P9: =E9 -> PolicyID
E10: Client ID | P10: Attachments
E11: PolicyNO | L11: RENEWALNotices | P11: DebitNote
L12: RNID | P12: Receipt
E13: Attachments | K13: M | L13: =E9 -> PolicyID | P13: PolicySchedule
E14: Proposal Form | P14: RenewalNotice
E15: Vehicle RC | P15: Payment Agreement
E16: Quotes
E17: QS Reports
E18: Photos
T28: SYSTEM | X28: DOCUMENTS | AB28: NOTIFICATIONS

Sheet P2
E2: POLICIES MANAGEMENT | T2: PREMIUM PAYMENTS MANAGEMENT
AB4: PAYMENTS
X5: DEBIT NOTES
T6: PAYMENTPLAN | Y6: 1 | AA6: M
P7: SCHEDULES | U7: 1 | W7: M
E8: POLICIES | Q8: 1 | S8: M
F9: 1 | O9: M
L11: RENEWALNotices
T13: COMMISSION MANAGEMENT
X16: COMMISSIONS
T17: Com NOTE | X17: ComID
T18: ComNoteID | U18: 1 | W18: M | X18: =T18 -> ComNoteID | AB18: COMStatement
S19: 1 | T19: ScheduleID | X19: =AB19 -> ComStatID | Y19: M | AA19: 1 | AB19: ComStatID
AB20: Attachments
AB21: ComStat
T28: SYSTEM | X28: DOCUMENTS | AB28: NOTIFICATIONS

Sheet P3
B2: CLIENTS | E2: POLICIES MANAGEMENT | T2: PREMIUM PAYMENTS MANAGEMENT
AB4: PAYMENTS
X5: DEBIT NOTES
T6: PAYMENTPLAN | Y6: 1 | AA6: M
P7: SCHEDULES | U7: 1 | W7: M
E8: POLICIES | Q8: 1 | S8: M
B9: CLIENTS | E9: PolicyID | F9: 1 | O9: M
B10: Client ID | C10: 1 | D10: M | E10: Client ID
B11: ClientType* | L11: RENEWALNotices
B12: Name
K13: M | T13: COMMISSION MANAGEMENT
B14: Attachments
B15: ID
B16: POA | X16: COMMISSIONS
B17: BusinessDocs | T17: Com NOTE
U18: 1 | W18: M | AB18: COMStatement
S19: 1 | Y19: M | AA19: 1
B21: BeneficialOwners
B22: BOID
B23: =B10 -> Client ID | C23: M
B24: Name
B26: Attachments
B27: ID
B28: POA | T28: SYSTEM | X28: DOCUMENTS | AB28: NOTIFICATIONS

Sheet P4
E2: POLICIES MANAGEMENT | T2: PREMIUM PAYMENTS MANAGEMENT
AB4: PAYMENTS
X5: DEBIT NOTES
T6: PAYMENTPLAN | Y6: 1 | AA6: M
P7: SCHEDULES | U7: 1 | W7: M
E8: POLICIES | Q8: 1 | S8: M
B9: CLIENTS | E9: PolicyID | F9: 1 | O9: M
C10: 1 | D10: M
L11: RENEWALNotices
T13: COMMISSION MANAGEMENT
X16: COMMISSIONS
L17: VEHICLES | T17: Com NOTE
L18: VehicleID | U18: 1 | W18: M | AB18: COMStatement
L19: PolicyID | S19: 1 | Y19: M | AA19: 1
E20: CLAIMS | L20: RegnNo
B21: BeneficialOwners | E21: ClaimID
E22: PolicyID | F22: M | L22: Attachments
C23: M | E23: Attachments | L23: SLTA Certificate
E24: ClaimForm | L24: Proof Of Purchase
E25: Other Docs | L25: Value Certificate
L27: ENDORSEMENTS
L28: EndorseID | T28: SYSTEM | X28: DOCUMENTS | AB28: NOTIFICATIONS
L29: PolicyID

Sheet P5
E2: POLICIES MANAGEMENT | T2: PREMIUM PAYMENTS MANAGEMENT | AF2: LEADS & LIFE INSURANCE
AB4: PAYMENTS | AJ4: PROPOSALS
X5: DEBIT NOTES | AF5: CONTACTS | AJ5: PRID | AK5: 1
T6: PAYMENTPLAN | Y6: 1 | AA6: M | AF6: ContactID | AG6: 1 | AI6: M | AJ6: =AF6 -> ContactID
P7: SCHEDULES | U7: 1 | W7: M
E8: POLICIES | Q8: 1 | S8: M
B9: CLIENTS | F9: 1 | O9: M | AJ9: MEDICALS
C10: 1 | D10: M | AF10: FOLLOWUPS | AJ10: MedID
L11: RENEWALNotices | AF11: FUID | AJ11: =AJ5 -> PRID | AK11: 1
AF12: =AF6 -> ContactID | AG12: M
T13: COMMISSION MANAGEMENT | AF13: =B10 -> 0
AF14: =AJ5 -> PRID
X16: COMMISSIONS
L17: VEHICLES | T17: Com NOTE
U18: 1 | W18: M | AB18: COMStatement
S19: 1 | Y19: M | AA19: 1
E20: CLAIMS
B21: BeneficialOwners
F22: M
C23: M
E27: NOMINEES | L27: ENDORSEMENTS
E28: NomineeID | T28: SYSTEM | X28: DOCUMENTS | AB28: NOTIFICATIONS
E29: =E9 -> 0 | F29: M
E30: Name
E31: Attachments
E32: IDS

Sheet P6
E2: POLICIES MANAGEMENT | T2: PREMIUM PAYMENTS MANAGEMENT | AF2: LEADS & LIFE INSURANCE
AB4: PAYMENTS | AJ4: PROPOSALS
X5: DEBIT NOTES | AF5: CONTACTS | AK5: 1
T6: PAYMENTPLAN | Y6: 1 | AA6: M | AG6: 1 | AI6: M
P7: SCHEDULES | U7: 1 | W7: M
E8: POLICIES | Q8: 1 | S8: M
B9: CLIENTS | F9: 1 | O9: M | AJ9: MEDICALS
C10: 1 | D10: M | AF10: FOLLOWUPS
L11: RENEWALNotices | AK11: 1
AG12: M
T13: COMMISSION MANAGEMENT
X16: COMMISSIONS
L17: VEHICLES | T17: Com NOTE
U18: 1 | W18: M | AB18: COMStatement
S19: 1 | Y19: M | AA19: 1
E20: CLAIMS
B21: BeneficialOwners
F22: M
C23: M
L27: ENDORSEMENTS
T28: SYSTEM | X28: DOCUMENTS | AB28: NOTIFICATIONS
AB32: TASKS

Sheet P7
E2: POLICIES MANAGEMENT | T2: PREMIUM PAYMENTS MANAGEMENT | AF2: LEADS & LIFE INSURANCE
AB4: PAYMENTS | AJ4: PROPOSALS
X5: DEBIT NOTES | AF5: CONTACTS | AK5: 1
T6: PAYMENTPLAN | Y6: 1 | AA6: M | AG6: 1 | AI6: M
P7: SCHEDULES | U7: 1 | W7: M
E8: POLICIES | Q8: 1 | S8: M
B9: CLIENTS | F9: 1 | O9: M | AJ9: MEDICALS
C10: 1 | D10: M | AF10: FOLLOWUPS
L11: RENEWALNotices | AK11: 1
AG12: M
T13: COMMISSION MANAGEMENT
X16: COMMISSIONS
L17: VEHICLES | T17: Com NOTE
U18: 1 | W18: M | AB18: COMStatement
S19: 1 | Y19: M | AA19: 1
E20: CLAIMS
B21: BeneficialOwners
F22: M
C23: M
L27: ENDORSEMENTS
T28: SYSTEM | X28: DOCUMENTS | AB28: NOTIFICATIONS
X32: REPORTS | AB32: TASKS

Sheet P8
E2: POLICIES MANAGEMENT | T2: PREMIUM PAYMENTS MANAGEMENT | AF2: LEADS & LIFE INSURANCE
AB4: PAYMENTS | AJ4: PROPOSALS
X5: DEBIT NOTES | AF5: CONTACTS | AK5: 1
T6: PAYMENTPLAN | Y6: 1 | AA6: M | AG6: 1 | AI6: M
P7: SCHEDULES | U7: 1 | W7: M
E8: POLICIES | Q8: 1 | S8: M
B9: CLIENTS | F9: 1 | O9: M | AJ9: MEDICALS
C10: 1 | D10: M | AF10: FOLLOWUPS
L11: RENEWALNotices | AK11: 1
AG12: M
T13: COMMISSION MANAGEMENT
X16: COMMISSIONS
L17: VEHICLES | T17: Com NOTE
U18: 1 | W18: M | AB18: COMStatement
S19: 1 | Y19: M | AA19: 1
E20: CLAIMS
B21: BeneficialOwners
F22: M
C23: M
L27: ENDORSEMENTS
T28: SYSTEM | X28: DOCUMENTS | AB28: NOTIFICATIONS
T32: CALENDAR | X32: REPORTS | AB32: TASKS

Sheet P9
E2: POLICIES MANAGEMENT | T2: PREMIUM PAYMENTS MANAGEMENT | AF2: LEADS & LIFE INSURANCE
AB4: PAYMENTS | AJ4: PROPOSALS
X5: DEBIT NOTES | AF5: CONTACTS | AK5: 1
T6: PAYMENTPLAN | Y6: 1 | AA6: M | AG6: 1 | AI6: M
P7: SCHEDULES | U7: 1 | W7: M
E8: POLICIES | Q8: 1 | S8: M
B9: CLIENTS | F9: 1 | O9: M | AJ9: MEDICALS
C10: 1 | D10: M | AF10: FOLLOWUPS
L11: RENEWALNotices | AK11: 1
AG12: M
T13: COMMISSION MANAGEMENT
X16: COMMISSIONS
L17: VEHICLES | T17: Com NOTE
U18: 1 | W18: M | AB18: COMStatement | AF18: FINANCIAL MANAGEMENT
S19: 1 | Y19: M | AA19: 1 | AC19: 1
E20: CLAIMS
B21: BeneficialOwners | AF21: INCOME | AJ21: TAX RETURN
F22: M | AF22: IncomeID | AJ22: TaxRetID
C23: M | AE23: 1 | AF23: ComStatID
AF24: Attachments
AF25: Bank Statements
L27: ENDORSEMENTS
T28: SYSTEM | X28: DOCUMENTS | AB28: NOTIFICATIONS | AF28: EXPENSES
AF29: ExpensesID
AF30: Attachments
AF31: Receipts
T32: CALENDAR | X32: REPORTS | AB32: TASKS

Sheet Lookups
A2: Contact Type | E2: Client Type | I2: Insurer | M2: Term | Q2: Payment Plan | U2: Claim Stage | Y2: Vehicle Make | AC2: ENDORSEMENT
A3: Seq | B3: Name | C3: Active | E3: Seq | F3: Name | G3: Active | I3: Seq | J3: Name | K3: Active | M3: Seq | N3: Name | O3: Active | Q3: Seq | R3: Name | S3: Active | U3: Seq | V3: Name | W3: Active | Y3: Seq | Z3: Name | AA3: Active | AC3: Seq | AD3: Type | AE3: Description
A4: 1 | B4: Lead | C4: Y | E4: 1 | F4: Individual | G4: Y | I4: 1 | J4: SACOS | K4: Y | M4: 1 | N4: Year | O4: Y | Q4: 1 | R4: Single | S4: Y | U4: 1 | V4: Awaiting Documents | Y4: 1 | Z4: Hyundai | AA4: Y | AC4: 1 | AD4: Renewal | AE4: Policy Renewed
A5: 2 | B5: Prospect | C5: Y | E5: 2 | F5: Business | G5: Y | I5: 2 | J5: HSavy | K5: Y | M5: 2 | N5: Days | O5: Y | Q5: 2 | R5: Split | S5: Y | U5: 2 | V5: Awaiting QS Report | Y5: 2 | Z5: Kia | AA5: Y | AC5: 2 | AD5: Cancelation | AE5: Policy Cancelled
A6: 3 | B6: Contact | C6: Y | E6: 3 | F6: Company | G6: Y | I6: 3 | J6: Alliance | K6: Y | M6: 4 | N6: Weeks | O6: Y | Q6: 3 | R6: Instalments | S6: Y | Y6: 3 | Z6: Suzuki | AA6: Y | AC6: 3 | AD6: Amendment | AE6: Sum Insured Reduced
A7: 4 | B7: SO Bank Officer | C7: Y | E7: 4 | F7: Organization | G7: Y | I7: 4 | J7: MUA | K7: N | Q7: 4 | R7: Regular (Life) | S7: Y | Y7: 4 | Z7: Toyota | AA7: Y | AC7: 4 | AD7: Amendment | AE7: Sum Insured Increased
A8: 5 | B8: Payroll Officer | C8: Y | U8: Claim Status | Y8: 5 | Z8: Ford | AA8: Y | AC8: 5 | AD8: Amendment | AE8: Plan Cover Changed
E9: ID Type | I9: Class | M9: Island | Q9: Mode Of Payment (Life) | U9: Seq | V9: Name | W9: Active | Y9: 6 | Z9: MG | AA9: Y | AC9: 6 | AD9: Amendment | AE9: Beneficary change
E10: Seq | F10: Name | G10: Active | I10: Seq | J10: Name | K10: Active | M10: Seq | N10: Name | O10: Active | Q10: Seq | R10: Name | S10: Active | U10: 1 | V10: Processing | W10: Y | Y10: 7 | Z10: Nissan | AA10: Y | AC10: 7 | AD10: Amendment | AE10: Pay Plan Changed
A11: Contact Stage | E11: 1 | F11: ID Card | G11: Y | I11: 1 | J11: Motor | K11: Y | M11: 1 | N11: Mahe | O11: Y | Q11: 1 | R11: Transfer | S11: Y | U11: 2 | V11: Settled | W11: Y | Y11: 8 | Z11: Mazda | AA11: Y | AC11: 8 | AD11: Amendment | AE11: Vehicle changed
A12: Seq | B12: Name | C12: Active | E12: 2 | F12: Driving License | G12: Y | I12: 2 | J12: General | K12: Y | M12: 2 | N12: Praslin | O12: Y | Q12: 2 | R12: Cheque | S12: Y | U12: 3 | V12: Declined | W12: Y | Y12: 9 | Z12: BMW | AA12: Y
A13: 1 | B13: Open | C13: Y | E13: 3 | F13: Passport | G13: Y | I13: 3 | J13: Life | K13: Y | M13: 3 | N13: La Digue | O13: Y | Q13: 3 | R13: Cash | S13: Y | Y13: 10 | Z13: Mercedes | AA13: Y
A14: 2 | B14: Qualified | C14: Y | E14: 4 | I14: 4 | J14: Bonds | K14: Y | M14: 4 | N14: Perseverance | O14: Y | Q14: 4 | R14: Online | S14: Y | Y14: 11 | Z14: Lexus | AA14: Y | AC14: Source Of Payment
A15: 3 | B15: KIV | C15: Y | I15: 5 | J15: Travel | K15: Y | M15: 5 | N15: Cerf | O15: Y | Q15: 5 | R15: Standing Order | S15: Y | U15: Income Category | Y15: 12 | Z15: Haval | AA15: Y | AC15: Seq | AD15: Source | AE15: Name
A16: 4 | B16: Closed | C16: Y | E16: Monthly Income | I16: 6 | J16: Marine | K16: Y | M16: 6 | N16: Eden | O16: Y | Q16: 6 | R16: Salary Deduction | S16: Y | U16: Seq | V16: Name | W16: Active | Y16: 13 | Z16: Honda | AA16: Y | AC16: 1 | AD16: Direct
E17: Seq | F17: Name | G17: Active | I17: 7 | J17: Health | K17: N | M17: 7 | N17: Silhouette | O17: Y | Q17: 7 | R17: Direect | S17: Y | U17: 1 | V17: Commission | W17: Y | Y17: 10 | Z17: Tata | AA17: Y | AC17: 2 | AD17: Online
A18: Contact Status | E18: 1 | F18: Less than 10,000 | G18: Y | M18: 8 | O18: Y | U18: 2 | V18: Bonus | W18: Y | Y18: 11 | Z18: Isuzu | AA18: Y | AC18: 3 | AD18: Bank | AE18: ABSA
A19: Seq | B19: Name | C19: Active | E19: 2 | F19: 10,001 to 20,000 | G19: Y | I19: Business Type | U19: 3 | V19: Prize | W19: Y | AC19: 4 | AE19: MCB
A20: 1 | B20: Not Contacted | C20: Y | E20: 3 | F20: 20,001 to 30,000 | G20: Y | I20: Seq | J20: Name | K20: Active | M20: Salutation | Q20: Mode Of Payment (General) | U20: 4 | V20: Other | W20: Y | AC20: 5 | AE20: NOU
A21: 2 | B21: Qualified | C21: Y | E21: 4 | F21: 30,001 to 40,000 | G21: Y | I21: 1 | J21: Direct | K21: Y | M21: Seq | N21: Name | O21: Active | Q21: Seq | R21: Name | S21: Active | Y21: Useage | AC21: 6 | AE21: BAR
A22: 3 | B22: Converted to Client | C22: Y | E22: 5 | F22: 40,001 to 50,000 | G22: Y | I22: 2 | J22: Transfer | K22: Y | M22: 1 | N22: Mr | O22: Y | Q22: 1 | R22: Cash | S22: Y | Y22: Seq | Z22: Name | AA22: Active | AC22: 7 | AE22: BOC
A23: 4 | B23: Keep In View | C23: Y | E23: 6 | F23: 50,001 and above | G23: Y | I23: 3 | J23: Renewal | K23: Y | M23: 2 | N23: Ms | O23: Y | Q23: 2 | R23: Card | S23: Y | U23: Expense Category | Y23: 1 | Z23: Private | AA23: Y | AC23: 8 | AE23: SCB
A24: 5 | B24: Archived | C24: Y | M24: 3 | N24: Mrs | O24: Y | Q24: 3 | R24: Transfer | S24: Y | U24: Seq | V24: Name | W24: Active | Y24: 2 | Z24: Commercial | AA24: Y | AC24: 9 | AE24: SCU
I25: Policy Status [Derived] | M25: 4 | N25: Miss | O25: Y | Q25: 4 | R25: Cheque | S25: Y | U25: 1 | V25: License | W25: Y | Y25: 3 | Z25: For Hire | AA25: Y | AC25: 10 | AE25: ASL
E26: Income Source | I26: Seq | J26: Name | K26: Active | M26: 5 | N26: Dr | O26: Y | U26: 2 | V26: Insurance | W26: Y | Y26: 4 | Z26: Carriage Of Goods | AA26: Y | AC26: 11 | AD26: Salary | AE26: AIRTEL
A27: Proposal Stage | E27: Seq | F27: Name | G27: Active | I27: 1 | J27: In Force | K27: Y | M27: 6 | N27: Mr & Mrs | O27: Y | U27: 3 | V27: Office supplies | W27: Y | Y27: 5 | Z27: Commuter | AA27: Y | AC27: 12 | AE27: Cable & Wireless
A28: Seq | B28: Name | C28: Active | E28: 1 | F28: Employment | G28: Y | I28: 2 | J28: Expired | K28: Y | Q28: PaymentType | U28: 4 | V28: Telephone & Internet | W28: Y | AC28: 13 | AE28: Intelvision
A29: 1 | B29: Not Contacted | C29: Y | E29: 2 | F29: Self Employed | G29: Y | I29: 3 | J29: Cancelled | K29: Y | Q29: Seq | R29: Name | S29: Active | U29: 5 | V29: Marketting | W29: Y | AC29: 14 | AE29: PUC
A30: 2 | B30: RNR | C30: Y | E30: 3 | F30: Business | G30: Y | J30: APL | M30: Agency | Q30: 1 | R30: Full | S30: Y | U30: 6 | V30: Travel | W30: Y | Y30: Vehicle Type | AC30: 15 | AE30: SFA
A31: 3 | B31: In Discussion | C31: Y | E31: 4 | F31: Investment | G31: Y | J31: Lapsed | M31: Seq | N31: Name | O31: Active | Q31: 2 | R31: Instalment | S31: Y | U31: 7 | V31: Referals | W31: Y | Y31: Seq | Z31: Name | AA31: Active | AC31: 16 | AE31: STC
A32: 4 | B32: Offer Made | C32: Y | E32: 5 | F32: Rentals | G32: Y | J32: Matured' | M32: 1 | N32: Keystone | O32: Y | Q32: 3 | R32: Adjustment | S32: Y | U32: 8 | V32: Rentals | W32: Y | Y32: 1 | Z32: SUV | AA32: Y | AC32: 17 | AE32: FSA
A33: 5 | B33: Proposal Filled | C33: Y | E33: 6 | F33: Retirement | G33: Y | J33: Surrenders | M33: 2 | N33: LIS | O33: Y | U33: 9 | V33: Vehicle | W33: Y | Y33: 2 | Z33: Hatchback | AA33: Y | AC33: 18 | AE33: Mins Of Education
E34: 7 | F34: Allowance | G34: Y | J34: Payout D | Q34: Payment Status | U34: 10 | V34: Fuel | W34: Y | Y34: 3 | Z34: Sedan | AA34: Y | AC34: 19 | AE34: Mins Of Health
E35: 8 | F35: Other | G35: Y | J35: Payout TPD | M35: Agent | Q35: Seq | R35: Name | S35: Active | U35: 11 | V35: Bank Fees | W35: Y | Y35: 4 | Z35: Twin Cab | AA35: Y | AC35: 20 | AE35: SFRSA
A36: Proposal Status | J36: Null & Void | M36: Seq | N36: Name | O36: Active | Q36: 1 | R36: Paid | S36: Y | U36: 12 | V36: Charges | W36: Y | Y36: 5 | Z36: Pick Up | AA36: Y | AC36: 21 | AE36: Seychelles Police
A37: Seq | B37: Name | C37: Active | M37: 1 | N37: Mandy | O37: Y | Q37: 2 | R37: Partly Paid | S37: Y | U37: 13 | V37: Misc | W37: Y | Y37: 6 | Z37: Scooter | AA37: Y | AC37: 22 | AE37: Treasury
A38: 1 | B38: Awaiting Medical | C38: Y | E38: Ranking | I38: ClientStatus [Derived] | M38: 2 | N38: Simon | O38: Y | Q38: 3 | R38: Unpaid | S38: Y | U38: 14 | V38: Asset Purchase | W38: Y | Y38: 7 | Z38: Motor Cycle | AA38: Y | AC38: 23 | AE38: Judiciary
A39: 2 | B39: Awaiting Policy | C39: Y | E39: Seq | F39: Name | G39: Active | I39: Seq | J39: Name | K39: Active | Y39: 8 | Z39: Taxi | AA39: Y | AC39: 24 | AE39: Pilgrims
A40: 3 | B40: Approved | C40: Y | E40: 1 | F40: VIP | G40: Y | I40: 1 | J40: Active | K40: Y | M40: Issuing Country | Q40: Frequency | Y40: 9 | Z40: Van | AA40: Y | AC40: 25 | AE40: SPTC
A41: 4 | B41: Declined | C41: Y | E41: 2 | F41: High | G41: Y | I41: 2 | J41: Dormant | K41: Y | M41: Seq | N41: Name | O41: Code | Q41: Seq | R41: Name | S41: Active | U41: Engine Type | Y41: 10 | AA41: Y
...

Sheet Status
B2: POLICIES | E2: CLIENTS | H2: CONTACTS | K2: PROPOSALS (LIFE)
B3: General | C3: Life
B4: Status | C4: Status | E4: Type | F4: Status | H4: Type | I4: Status | K4: Status
H5: Lead | I5: Open | K5: Offer Made
I6: Not Reached | K6: Form Filled
I7: Archived | K7: Awaiting documents
H8: Prospect | I8: In Discussion | K8: Awaiting Deposit
I9: Offer Made | K9: Submitted
I10: Archived | K10: Awaiting Medical
I11: KIV | K11: Awaiting Policy
H12: Contact | I12: Active | K12: Declined
I13: Archived | K13: Withdrawn
K14: Approved
B16: In Force | C16: In Force | E16: Individual | F16: Active
B17: Cancelled | C17: APL | E17: Business
B18: Expired | C18: Matured | E18: Company
B19: Archived | C19: Cancelled | E19: Organisation
C20: Surrendered | E20: Individual | F20: Dormant
C21: TPD Payout | E21: Business
C22: Death Payout | E22: Company
C23: Null & Void | E23: Organisation

Sheet DASH
E2: Dashboard
F6: 1 | I6: 1 | M6: 1 | Q6: 1 | U6: 121 | Y6: 3265.23
D7: Tasks Today | H7: Policies Expiring | L7: Instalments Overdue | P7: IDs Expired | T7: General Policies | X7: Gen-Com Outstanding
F11: 7 | I11: 7 | M11: 11 | Q11: 7 | U11: 239 | Y11: 1
D12: Open Leads | H12: Follow Ups Today | L12: Proposals Pending | Q12: Proposals Processing | U12: Life Policies | X12: Birthdays Today
E16: Income v/s Expense | I16: 2024 | M16: Income | Q16: =I16 -> 2024 | U16: Expenses | Y16: =I16 -> 2024
E18: From : | F18: 45292 | H18: To : | I18: 45657
F19: 253000 | I19: 225023

Sheet CFU
E2: Follow Ups - Contacts
E4: Records Found - 11
F6: Action | G6: Contact Name | H6: Category | I6: Contact No | J6: Date | K6: Time | L6: Type | M6: Assigned | N6: Status | O6: Close Date | P6: Follow Up Notes | Q6: 1st Called | R6: Rank | S6: Next FU | W6: Status | X6: Agency | Y6: Address | Z6: Employer | AA6: Contact ID | AB6: Savings Budget | AC6: Married | AD6: Children | AE6: Children Details | AF6: Vehicle | AG6: House | AH6: Business | AI6: Other
G7: Wanda Lucas | H7: Prospect | I7: 4423212 | J7: =TODAY() -> 45952 | K7: 1000 | L7: Call | M7: Mandy | N7: Not Done | Q7: =TODAY()-7 -> 45945 | R7: Warm | W7: Active | X7: Keystone | Y7: Beau Vallon | Z7: SEYPEC | AA7: LD24-0077
G8: Debra Grey | H8: Lead | I8: 2511611 | J8: =TODAY() -> 45952 | K8: 1000 | L8: Follow Up | M8: Mandy | N8: Not Done | Q8: =TODAY()-9 -> 45943 | R8: Hot | W8: Active | X8: Keystone | Y8: Mont Fleuri | Z8: Cable & Wireless | AA8: LD24-0076
G9: Sheila Ewang | H9: Lead | I9: 2765432 | J9: =TODAY() -> 45952 | K9: 1000 | L9: Follow Up | M9: Mandy | N9: Not Done | Q9: =TODAY()-45 -> 45907 | R9: Warm | W9: Active | X9: Keystone | Y9: Beau Vallon | Z9: AIRTEL | AA9: LD24-0075
G10: Kirk Patrick | H10: Lead | I10: 4373234 | J10: =TODAY() -> 45952 | K10: 1000 | L10: Follow Up | M10: Mandy | N10: Not Done | Q10: =TODAY()-30 -> 45922 | R10: Warm | W10: Active | X10: Keystone | Y10: Cascade | AA10: LD24-0074
G11: Scott Svenson | H11: Lead | I11: 4378645 | J11: =TODAY() -> 45952 | K11: 1000 | L11: Meeting | M11: Mandy | N11: Not Done | Q11: =TODAY()-30 -> 45922 | R11: KIV | W11: In Active | X11: Keystone | Y11: Victoria | AA11: LD24-0073
G12: Samuel Hill | H12: Lead | I12: 2514231 | J12: =TODAY() -> 45952 | K12: 1000 | L12: Follow Up | M12: Mandy | N12: Not Done | Q12: =TODAY()-25 -> 45927 | R12: Warm | W12: Active | Y12: Mont Fleuri | Z12: SPTC | AA12: LD24-0073
G13: Kaste McEwan | H13: Lead | I13: 2765887 | J13: =TODAY() -> 45952 | K13: 1000 | L13: Follow Up | M13: Mandy | N13: Not Done | Q13: 45439 | R13: Warm | W13: Active | X13: Keystone | Y13: Beau Vallon | Z13: Inter Island Boats | AA13: LD24-0072
G14: Mary Trader | H14: Lead | I14: 4373234 | J14: =TODAY()-1 -> 45951 | K14: 1000 | L14: Call | M14: Mandy | N14: Not Done | Q14: 45432 | R14: Warm | W14: Active | X14: Keystone | Y14: Providence | AA14: LD24-0071
G15: Damien Kinmo | H15: Lead | I15: 2787653 | J15: =TODAY()-1 -> 45951 | K15: 1000 | L15: Call | M15: Mandy | N15: Not Done | Q15: 30602 | R15: Warm | W15: Active | X15: Keystone | Y15: Grand Anse | AA15: LD24-0070
G16: Dua Gomez | H16: Lead | I16: 4378645 | J16: =TODAY()-2 -> 45950 | K16: 1000 | L16: Follow Up | M16: Mandy | N16: Not Done | Q16: 45387 | R16: KIV | W16: Active | Y16: Mont Fleuri | Z16: SPTC | AA16: LD24-0073
G17: Cox Santana | H17: Lead | I17: 4378677 | J17: =TODAY()-3 -> 45949 | K17: 1000 | L17: Follow Up | M17: Mandy | N17: Not Done | Q17: 45387 | R17: Warm | W17: Active | X17: Keystone | Y17: Beau Vallon | Z17: Inter Island Boats | AA17: LD24-0072
W18: Active | X18: Keystone | Y18: Providence | AA18: LD24-0071
W19: Active | X19: Keystone | Y19: Grand Anse | AA19: LD24-0070
W20: Active | X20: Keystone | Y20: Anse Aux Pins | Z20: Avani Hotel | AA20: LD24-0069
W21: Active | X21: Keystone | Y21: Grand Anse | AA21: LD24-0070

Sheet UR
E2: Upcoming Renewals
E4: Records 1 to 4 of 4
F6: Action | G6: Policy No | H6: Policy No | I6: Policy No | J6: Client Name | K6: Policy Class | L6: Policy Plan | M6: Insurer | N6: Sum Insured | O6: Premium | P6: Start Date | Q6: End Date | R6: Regn No | S6: Status
G7: 1 | I7: MPV-23-HEA-P0002132 | J7: Jean Grey | K7: Motor | L7: Comprehensive | M7: SACOS | N7: 390000 | O7: 11455.893 | P7: =Q7-365 -> 45592 | Q7: =TODAY()+5 -> 45957 | R7: S44444 | S7: DFR
G8: 2 | I8: HS1-22-HIN-000321 | J8: Tom Thumb | K8: General | L8: House Insurance | M8: Hsavy | N8: 2500000 | O8: =X8*1.16 -> 0 | P8: 45234 | Q8: 45615 | S8: DFR
G9: 3 | I9: PL-22-ALP-000033 | J9: Cornerstone (Pty) Ltd | K9: General | L9: Public Liability | M9: Alliance | N9: 2000000 | O9: =X9*1.16 -> 0 | P9: 45245 | Q9: =TODAY()+9 -> 45961 | S9: DFR
G10: 4 | I10: HS1-23-P00023132 | J10: Cornerstone (Pty) Ltd | K10: General | L10: Employer's Liabilithy | M10: Alliance | N10: 1000000 | O10: 2900 | P10: 45247 | Q10: =TODAY()+9 -> 45961 | S10: DFR

Sheet POD
E2: Premium Overdue
E4: Reocrds Found - 1
F6: Action | G6: Debit Note | H6: Debit Note | I6: Debit Note | J6: Date Due | K6: Amount Due | L6: Status | M6: Policy Number | O6: Client Name
G7: 1 | I7: DN23100 | J7: =TODAY()-1 -> 45951 | K7: 5727.9466 | L7: Unpaid | M7: MPV-23-HEA-P00002132 | O7: Jean Grey

Sheet Pex
E2: Policies Expiring
E4: Records Found - 1 | P4: `
F6: Action | G6: Policy No | H6: Policy No | I6: Policy No | J6: Client Name | K6: Policy Class | L6: Insurer | M6: Insured Item | N6: Regn No | O6: Last Premium | P6: End Date | Q6: Status | R6: Days
G7: 1 | I7: HS1-072-HEA-P0002011 | J7: Basil Walton | K7: General | L7: Hsavy | M7: Residence at Belombre | O7: 5043 | P7: =TODAY() -> 45952 | Q7: =IF(P7<TODAY(),"Expired","") | R7: =P7-TODAY() -> 0

Sheet OL
E2: Open Leads
E4: Records Found - 7
F6: Action | G6: Contact Name | H6: Type | I6: Source | J6: Source Name | K6: Acquired | L6: Aging | M6: Contact No | N6: Occupation | P6: 1st Called | Q6: 2FU | R6: Next FU | S6: Next FU | T6: Ranking | U6: Status | X6: Status | Y6: Agency | Z6: Address | AA6: Employer | AB6: Contact ID | AC6: Savings Budget | AD6: Married | AE6: Children | AF6: Children Details | AG6: Vehicle | AH6: House | AI6: Business | AJ6: Other
G7: Blake Banks | H7: Lead | I7: Direct | K7: =TODAY() -> 45952 | L7: =TODAY()-K7 -> 0 | M7: 2511611 | N7: Accountant | T7: Hot | U7: Open | X7: Active | Y7: Keystone | Z7: Beau Vallon | AA7: SEYPEC | AB7: LD24-0077
G8: Kim Rider | H8: Lead | I8: Referal | J8: Greta Sams | K8: =TODAY() -> 45952 | L8: =TODAY()-K8 -> 0 | M8: 4423212 | N8: Driver | T8: Hot | U8: Open | X8: Active | Y8: Keystone | Z8: Mont Fleuri | AA8: Cable & Wireless | AB8: LD24-0076
G9: Tamara Vincent | H9: Lead | I9: Referal | J9: Greta Sams | K9: =TODAY()-4 -> 45948 | L9: =TODAY()-K9 -> 4 | M9: 2765432 | N9: Customer Service Officer | U9: Open | X9: Active | Y9: Keystone | Z9: Beau Vallon | AA9: AIRTEL | AB9: LD24-0075
G10: Kate Boom | H10: Lead | I10: Referal | J10: Brandon Smith | K10: =TODAY()-4 -> 45948 | L10: =TODAY()-K10 -> 4 | M10: 2876565 | N10: Driver | T10: Warm | U10: Open | X10: Active | Y10: Keystone | Z10: Cascade | AB10: LD24-0074
G11: Ian Dirk | H11: Lead | I11: Referal | J11: Gary Foster | K11: =TODAY()-6 -> 45946 | L11: =TODAY()-K11 -> 6 | M11: 6212143 | N11: Tailor | T11: Warm | U11: Open | X11: In Active | Y11: Keystone | Z11: Victoria | AB11: LD24-0073
G12: Orlando Mendez | H12: Lead | I12: Direct | K12: =TODAY()-4 -> 45948 | L12: =TODAY()-K12 -> 4 | M12: 4323232 | N12: Plumber | U12: Open | X12: Active | Z12: Mont Fleuri | AA12: SPTC | AB12: LD24-0073
G13: Sandra Diaz | H13: Lead | I13: Direct | K13: =TODAY()-6 -> 45946 | L13: =TODAY()-K13 -> 6 | M13: 2786543 | N13: Police Officer | U13: Open | X13: Active | Y13: Keystone | Z13: Beau Vallon | AA13: Inter Island Boats | AB13: LD24-0072
X14: Active | Y14: Keystone | Z14: Providence | AB14: LD24-0071
X15: Active | Y15: Keystone | Z15: Grand Anse | AB15: LD24-0070
X16: Active | Z16: Mont Fleuri | AA16: SPTC | AB16: LD24-0073
X17: Active | Y17: Keystone | Z17: Beau Vallon | AA17: Inter Island Boats | AB17: LD24-0072
X18: Active | Y18: Keystone | Z18: Providence | AB18: LD24-0071
X19: Active | Y19: Keystone | Z19: Grand Anse | AB19: LD24-0070
X20: Active | Y20: Keystone | Z20: Anse Aux Pins | AA20: Avani Hotel | AB20: LD24-0069
X21: Active | Y21: Keystone | Z21: Grand Anse | AB21: LD24-0070

Sheet Cal
E2: Calendar
E5: 2025 | F5: JUNE
E7: MON | F7: TUE | G7: WED | H7: THU | I7: FRI | J7: SAT | K7: SUN
E8: 26 | F8: 27 | G8: 28 | H8: 29 | I8: 30 | J8: 31 | K8: 1
F9: License Fee
E12: 2 | F12: 3 | G12: 4 | H12: 5 | I12: 6 | J12: 7 | K12: 8
F13: Suesan Voicy | G13: Kevin Minion | H13: Patrick Ewan | I13: Steve Ball
E16: 9 | F16: 10 | G16: 11 | H16: 12 | I16: 13 | J16: 14 | K16: 15
F17: Bruce Terry | H17: Samantha Farley | K17: Jeffery Albany
F18: Hazel Gator | H18: Ellie Bailey
E20: 16 | F20: 17 | G20: 18 | I20: 20 | J20: 21 | K20: 22
H21: Jeffery Albany
H22: Gary Totem
E24: 23 | F24: 24 | G24: 25 | H24: 26 | I24: 27 | J24: 28 | K24: 29
E25: Timothy Charlston | F25: Brandon Yale | G25: Heather Swift
E26: Graham Rust
E28: 30 | F28: 1 | G28: 2 | H28: 3 | I28: 4 | J28: 5 | K28: 6
H29: P.O. Box Rental
H30: Shery Nathan

Sheet CalT
E2: Calendar
E5: 2025 | F5: JUNE
E7: MON | F7: TUE | G7: WED | H7: THU | I7: FRI | J7: SAT | K7: SUN
E8: 26 | F8: 27 | G8: 28 | H8: 29 | I8: 30 | J8: 31 | K8: 1
F9: License Fee
E12: 2 | F12: 3 | G12: 4 | H12: 5 | I12: 6 | J12: 7 | K12: 8
E16: 9 | F16: 10 | G16: 11 | H16: 12 | I16: 13 | J16: 14 | K16: 15
E20: 16 | F20: 17 | G20: 18 | I20: 20 | J20: 21 | K20: 22
E24: 23 | F24: 24 | G24: 25 | H24: 26 | I24: 27 | J24: 28 | K24: 29
E28: 30 | F28: 1 | G28: 2 | H28: 3 | I28: 4 | J28: 5 | K28: 6
H29: P.O. Box Rental

Sheet CalF
E2: Calendar
E5: 2025 | F5: JUNE
E7: MON | F7: TUE | G7: WED | H7: THU | I7: FRI | J7: SAT | K7: SUN
E8: 26 | F8: 27 | G8: 28 | H8: 29 | I8: 30 | J8: 31 | K8: 1
I9: Davis Trent
E12: 2 | F12: 3 | G12: 4 | H12: 5 | I12: 6 | J12: 7 | K12: 8
G13: Kevin Minion | I13: Steve Ball
E16: 9 | F16: 10 | G16: 11 | H16: 12 | I16: 13 | J16: 14 | K16: 15
F17: Bruce Terry | H17: Samantha Farley
F18: Hazel Gator
E20: 16 | F20: 17 | G20: 18 | I20: 20 | J20: 21 | K20: 22
E24: 23 | F24: 24 | G24: 25 | H24: 26 | I24: 27 | J24: 28 | K24: 29
E28: 30 | F28: 1 | G28: 2 | H28: 3 | I28: 4 | J28: 5 | K28: 6

Sheet CalR
E2: Calendar
E5: 2025 | F5: JUNE
E7: MON | F7: TUE | G7: WED | H7: THU | I7: FRI | J7: SAT | K7: SUN
E8: 26 | F8: 27 | G8: 28 | H8: 29 | I8: 30 | J8: 31 | K8: 1
I9: Davis Trent
E12: 2 | F12: 3 | G12: 4 | H12: 5 | I12: 6 | J12: 7 | K12: 8
F13: Suesan Voicy | H13: Patrick Ewan
E16: 9 | F16: 10 | G16: 11 | H16: 12 | I16: 13 | J16: 14 | K16: 15
H18: Ellie Bailey
E20: 16 | F20: 17 | G20: 18 | I20: 20 | J20: 21 | K20: 22
H21: Gary Totem
E24: 23 | F24: 24 | G24: 25 | H24: 26 | I24: 27 | J24: 28 | K24: 29
E25: Graham Rust | F25: Brandon Yale | G25: Heather Swift
E28: 30 | F28: 1 | G28: 2 | H28: 3 | I28: 4 | J28: 5 | K28: 6
H29: Shery Nathan

Sheet CalI
E2: Calendar
E5: 2025 | F5: JUNE
E7: MON | F7: TUE | G7: WED | H7: THU | I7: FRI | J7: SAT | K7: SUN
E8: 26 | F8: 27 | G8: 28 | H8: 29 | I8: 30 | J8: 31 | K8: 1
E12: 2 | F12: 3 | G12: 4 | H12: 5 | I12: 6 | J12: 7 | K12: 8
E16: 9 | F16: 10 | G16: 11 | H16: 12 | I16: 13 | J16: 14 | K16: 15
K17: Jeffery Albany
E20: 16 | F20: 17 | G20: 18 | I20: 20 | J20: 21 | K20: 22
H21: Jeffery Albany
E24: 23 | F24: 24 | G24: 25 | H24: 26 | I24: 27 | J24: 28 | K24: 29
E25: Timothy Charlston
E28: 30 | F28: 1 | G28: 2 | H28: 3 | I28: 4 | J28: 5 | K28: 6

Sheet CalB
E2: Calendar
E5: 2025 | F5: JUNE
E7: MON | F7: TUE | G7: WED | H7: THU | I7: FRI | J7: SAT | K7: SUN
E8: 26 | F8: 27 | G8: 28 | H8: 29 | I8: 30 | J8: 31 | K8: 1
I9: Davis Trent
E12: 2 | F12: 3 | G12: 4 | H12: 5 | I12: 6 | J12: 7 | K12: 8
I13: Susan Voysey | K13: Patrick Ewans
E16: 9 | F16: 10 | G16: 11 | H16: 12 | I16: 13 | J16: 14 | K16: 15
G17: Hazel Gator | J17: Samantha Farley
E20: 16 | F20: 17 | G20: 18 | I20: 20 | J20: 21 | K20: 22
J21: Jeffrey Albany
E24: 23 | F24: 24 | G24: 25 | H24: 26 | I24: 27 | J24: 28 | K24: 29
F25: Timothy Charleton | G25: Brandon Yale | I25: Heather Graham
F26: Candy Grallance
E28: 30 | F28: 1 | G28: 2 | H28: 3 | I28: 4 | J28: 5 | K28: 6

Sheet LB
A1: `
E2: Birthday List - December
E4: Records Found - 10
F6: Action | G6: Name | I6: Date Of Birth | J6: Age | K6: Client Status | L6: Mobile No | N6: Contact No | O6: Home No | P6: Email Address | Q6: Medium | R6: Wish Status | S6: Date Done
G7: Davis Trent | I7: 29371 | J7: =(TODAY()-I7)/365 -> 45.427397 | K7: Active | L7: 2713214 | M7: Y | N7: 4232323 | P7: Davis.trent@yahoo.com | Q7: Wattsapp | R7: Not Done
G8: Susan Voysey | I8: 30108 | J8: =(TODAY()-I8)/365 -> 43.408219 | K8: Active | L8: 2511777 | M8: Y | Q8: Wattsapp | R8: Done | S8: 45632
G9: Patrick Ewans | I9: 28284 | J9: =(TODAY()-I9)/365 -> 48.405479 | K9: Active | L9: 2817324 | N9: 2711511 | Q9: SMS | R9: Not Done
G10: Hazel Gator | I10: 32670 | J10: =(TODAY()-I10)/365 -> 36.389041 | K10: Dormant | L10: 2558722 | N10: 4378645 | Q10: SMS | R10: Not Done
G11: Samantha Farley | I11: 32308 | J11: =(TODAY()-I11)/365 -> 37.380822 | K11: Active | L11: 2883204 | N11: 4378645 | P11: sfarley99@gmail.com | Q11: Email | R11: Sent | S11: =I11 -> 32308
G12: Jeffrey Albany | I12: 28662 | J12: =(TODAY()-I12)/365 -> 47.369863 | K12: Active | L12: 2751112 | M12: Y | O12: 4754332 | Q12: Call | R12: Done | S12: =I12 -> 28662
G13: Timothy Charleton | I13: 33779 | J13: =(TODAY()-I13)/365 -> 33.350685 | K13: Active | O13: 4617232 | Q13: Call | R13: No Reply
G14: Candy Grallance | I14: 28665 | J14: =(TODAY()-I14)/365 -> 47.361644 | K14: Active | L14: 2731213 | M14: Y | O14: 4783299 | Q14: Call | R14: Done | S14: =I14 -> 28665
G15: Brandon Yale | I15: 34510 | J15: =(TODAY()-I15)/365 -> 31.347945 | K15: Active | L15: 2563213 | M15: Y | O15: 4612329 | Q15: Call | R15: Done | S15: =I15 -> 34510
G16: Heather Graham | I16: 30860 | J16: =(TODAY()-I16)/365 -> 41.347945 | K16: Active | L16: 2810654 | Q16: SMS | R16: Done | S16: =I16 -> 30860

Sheet LT
A1: `
F2: Tasks
F4: Records Found - 14
E6: No | G6: Action | H6: Task ID | I6: Task ID | J6: Category | K6: Description | L6: Name | M6: Contact No | N6: Due Date | O6: Time | P6: Due in | Q6: Assignee | R6: Task Status | S6: Date Done | T6: Repeat | U6: Frequency | X6: Rpt Date | Y6: Rpt Stop Date | Z6: Task ID
E7: 1 | I7: TK24088 | J7: Payment | K7: P.O. Box Rental | L7: Seychelles Postal Services | M7: 2765997 | N7: =TODAY()+14 -> 45966 | P7: =N7-TODAY() -> 14 | Q7: Mandy | R7: Not Done | T7: Y | U7: Annually | X7: 45701 | Z7: TK24088
E8: 2 | I8: TK24087 | J8: Report | K8: Beneficial Owner Report | L8: FIU | M8: 4282828 | N8: =TODAY()+12 -> 45964 | P8: =N8-TODAY() -> 12 | Q8: Mandy | R8: Not Done | T8: Y | U8: Bi Annually | X8: 45699 | Z8: TK24087
E9: 3 | I9: TK24086 | J9: Payment | K9: Brokers License | L9: FSA | M9: 4378645 | N9: =TODAY()+8 -> 45960 | P9: =N9-TODAY() -> 8 | Q9: Simon | R9: Not Done | T9: Y | U9: Annually | X9: 45695 | Z9: TK24086
E10: 4 | I10: TK24085 | J10: Event | K10: Presentation | L10: Hunt Deltel | M10: 4232323 | N10: =TODAY()+8 -> 45960 | O10: 1600 | P10: 12 | Q10: Mandy | R10: Not Done | T10: N | Z10: TK24085
E11: 5 | I11: TK24084 | J11: Payment | K11: PI Insurance Renewal | L11: Alliance | M11: 4223434 | N11: =TODAY()+7 -> 45959 | P11: =N11-TODAY() -> 7 | Q11: Mandy | R11: Not Done | T11: Y | U11: Annually | X11: 45694 | Z11: TK24084
E12: 6 | I12: TK24083 | J12: Payment | K12: Annual Registration Fee | L12: Registrar Of Companies | M12: 2711511 | N12: =TODAY()+4 -> 45956 | P12: 13 | Q12: Mandy | R12: Not Done | T12: Y | U12: Annually | X12: 45691 | Z12: TK24083
E13: 7 | I13: TK24082 | J13: Report | K13: Financial Audit Report | L13: FSA | M13: 4378645 | N13: =TODAY()+1 -> 45953 | P13: =N13-TODAY() -> 1 | Q13: Simon | R13: Not Done | T13: Y | U13: Annually | X13: 45688 | Z13: TK24082
E14: 8 | I14: TK24081 | J14: Report | K14: Bi Annuall CFT Report | L14: FSA | M14: 4378645 | N14: =TODAY()-3 -> 45949 | P14: =N14-TODAY() -> -3 | Q14: Simon | R14: Not Done | T14: Y | U14: Bi Annually | X14: 45687 | Z14: TK24081
E15: 9 | I15: TK24080 | J15: Report | K15: Tax Return | L15: Seychelles Revenue Commission | M15: 4287555 | N15: =TODAY()-1 -> 45951 | P15: =N15-TODAY() -> -1 | Q15: Simon | R15: In Progress | T15: Y | U15: Annually | X15: 45685 | Z15: TK24080
E16: 10 | I16: TK24079 | J16: Report | K16: Compliance Report | L16: FSA | M16: 4378645 | N16: 45672 | Q16: Mandy | R16: Completed | S16: 45682 | T16: Y | U16: Annually | X16: 45672 | Z16: TK24079
E17: 11 | I17: TK24078 | J17: Payment | K17: Deposit Premium | L17: Randy Crax | M17: 4756599 | N17: 45669 | O17: 1130 | Q17: Simon | R17: Completed | S17: 45669 | T17: N | Z17: TK24078
E18: 12 | I18: TK24077 | J18: Payment | K18: Deposit Premium | L18: Bella Vista | M18: 2727254 | N18: 45664 | Q18: Simon | R18: Completed | S18: 45664 | T18: N | X18: 45664 | Z18: TK24077
E19: 13 | I19: TK24076 | J19: Payment | K19: Deposit Premium | L19: Deep Divers | M19: 2815655 | N19: 45661 | Q19: Simon | R19: Completed | S19: 45661 | T19: N | X19: 45661 | Z19: TK24076
E20: 14 | I20: TK24075 | J20: Meeting | K20: Life Proposal | L20: Sam Anadro | M20: 2711090 | N20: 45651 | O20: 1030 | Q20: Simon | R20: Completed | S20: 46016 | T20: N | Z20: TK24075

Sheet AT
A1: `
E2: Tasks
E4: Records Found - 14
J6: Task ID | K6: Category | L6: Item | M6: Name | N6: Contact No | O6: Reminder | P6: Due Date | Q6: Due in | R6: Assignee | S6: Task Status | T6: Done Date | U6: Repeat | V6: Frequency
J7: TK24088 | K7: Payment | L7: P.O. Box Rental | M7: Seychelles Postal Services | N7: 2765997 | O7: =P7-30 -> 45936 | P7: =TODAY()+14 -> 45966 | Q7: =P7-TODAY() -> 14 | R7: Mandy | S7: Not Done | U7: Y | V7: Annually
J8: TK24087 | K8: Report | L8: Beneficial Owner Report | M8: FIU | N8: 4282828 | O8: =P8-30 -> 45934 | P8: =TODAY()+12 -> 45964 | Q8: =P8-TODAY() -> 12 | R8: Mandy | S8: Not Done | U8: Y | V8: Bi Annually
J9: TK24086 | K9: Payment | L9: Brokers License | M9: FSA | N9: 4378645 | O9: =P9-30 -> 45930 | P9: =TODAY()+8 -> 45960 | Q9: =P9-TODAY() -> 8 | R9: Simon | S9: Not Done | U9: Y | V9: Annually
J10: TK24085 | K10: To Do | L10: Presentation | M10: Hunt Deltel | N10: 4232323 | O10: =P10-30 -> 45930 | P10: =TODAY()+8 -> 45960 | Q10: 12 | R10: Mandy | S10: Not Done | U10: N
J11: TK24084 | K11: Payment | L11: PI Insurance Renewal | M11: Alliance | N11: 4223434 | O11: =P11-30 -> 45929 | P11: =TODAY()+7 -> 45959 | Q11: =P11-TODAY() -> 7 | R11: Mandy | S11: Not Done | U11: Y | V11: Annually
J12: TK24083 | K12: Payment | L12: Annual Registration Fee | M12: Registrar Of Companies | N12: 2711511 | O12: =P12-30 -> 45926 | P12: =TODAY()+4 -> 45956 | Q12: 13 | R12: Mandy | S12: Not Done | U12: Y | V12: Annually
J13: TK24082 | K13: Report | L13: Financial Audit Report | M13: FSA | N13: 4378645 | O13: =P13-30 -> 45923 | P13: =TODAY()+1 -> 45953 | Q13: =P13-TODAY() -> 1 | R13: Simon | S13: Not Done | U13: Y | V13: Annually
J14: TK24081 | K14: Report | L14: Bi Annuall CFT Report | M14: FSA | N14: 4378645 | O14: =P14-30 -> 45922 | P14: =TODAY()+0 -> 45952 | Q14: 14 | R14: Simon | S14: Not Done | U14: Y | V14: Bi Annually
J15: TK24080 | K15: To Do | L15: Tax Return | M15: Seychelles Trevenue Commission | N15: 4287555 | O15: =P15-30 -> 45920 | P15: =TODAY()-2 -> 45950 | Q15: =P15-TODAY() -> -2 | R15: Simon | S15: In Progress | U15: Y | V15: Annually
J16: TK24079 | K16: Report | L16: Compliance Report | M16: FSA | N16: 4378645 | O16: =P16-30 -> 45642 | P16: 45672 | R16: Mandy | S16: Completed | U16: Y | V16: Annually
J17: TK24078 | K17: Follow Up | L17: Life Proposal | M17: Randy Crax | N17: 4756599 | O17: =P17-30 -> 45639 | P17: 45669 | R17: Simon | S17: Completed | U17: N
J18: TK24077 | K18: Renewal | L18: Send Renewal Notice | M18: Bella Vista | N18: 2727254 | O18: =P18-30 -> 45634 | P18: 45664 | R18: Simon | S18: Completed | U18: Y | V18: Annually
J19: TK24076 | K19: Reminder | L19: Send Reminder | M19: Deep Divers | N19: 2815655 | O19: =P19-30 -> 45631 | P19: 45661 | R19: Simon | S19: Completed | U19: Y | V19: Annually
J20: TK24075 | K20: Meeting | L20: Life Proposal | M20: Sam Anadro | N20: 2711090 | O20: =P20-30 -> 45621 | P20: 45651 | R20: Simon | S20: Completed | U20: N

Sheet VT
A1: `
E2: Tasks
E4: Records Found - 14
J6: Task ID | K6: Category | L6: Task Note | M6: Target | N6: Contact No | O6: Due Date | P6: Due in | Q6: Assignee | R6: Task Status | S6: Done Date | T6: Repeat | U6: Frequency | X6: RptStopDate
J7: TK24088 | K7: Payment | L7: P.O. Box Rental | M7: Seychelles Postal Services | N7: 2765997 | O7: =TODAY()+14 -> 45966 | P7: =O7-TODAY() -> 14 | Q7: Mandy | R7: Not Done | T7: Y
J8: TK24087 | K8: Report | L8: Beneficial Owner Report | M8: FIU | N8: 4282828 | O8: =TODAY()+12 -> 45964 | P8: =O8-TODAY() -> 12 | Q8: Mandy | R8: Not Done | T8: Y | U8: Bi Annually
J9: TK24086 | K9: Payment | L9: Brokers License | M9: FSA | N9: 4378645 | O9: =TODAY()+8 -> 45960 | P9: =O9-TODAY() -> 8 | Q9: Simon | R9: Not Done | T9: Y | U9: Annually
J10: TK24085 | K10: To Do | L10: Presentation | M10: Hunt Deltel | N10: 4232323 | O10: =TODAY()+8 -> 45960 | P10: 12 | Q10: Mandy | R10: Not Done | T10: N
J11: TK24084 | K11: Payment | L11: PI Insurance Renewal | M11: Alliance | N11: 4223434 | O11: =TODAY()+7 -> 45959 | P11: =O11-TODAY() -> 7 | Q11: Mandy | R11: Not Done | T11: Y | U11: Annually
J12: TK24083 | K12: Payment | L12: Annual Registration Fee | M12: Registrar Of Companies | N12: 2711511 | O12: =TODAY()+4 -> 45956 | P12: 13 | Q12: Mandy | R12: Not Done | T12: Y | U12: Annually
J13: TK24082 | K13: Report | L13: Financial Audit Report | M13: FSA | N13: 4378645 | O13: =TODAY()+1 -> 45953 | P13: =O13-TODAY() -> 1 | Q13: Simon | R13: Not Done | T13: Y | U13: Annually
J14: TK24081 | K14: Report | L14: Bi Annuall CFT Report | M14: FSA | N14: 4378645 | O14: =TODAY()+0 -> 45952 | P14: 14 | Q14: Simon | R14: Not Done | T14: Y | U14: Bi Annually
J15: TK24080 | K15: To Do | L15: Tax Return | M15: Seychelles Trevenue Commission | N15: 4287555 | O15: =TODAY()-2 -> 45950 | P15: =O15-TODAY() -> -2 | Q15: Simon | R15: In Progress | T15: Y | U15: Annually
J16: TK24079 | K16: Report | L16: Compliance Report | M16: FSA | N16: 4378645 | O16: 45672 | Q16: Mandy | R16: Completed | T16: Y | U16: Annually
J17: TK24078 | K17: Follow Up | L17: Life Proposal | M17: Randy Crax | N17: 4756599 | O17: 45669 | Q17: Simon | R17: Completed | T17: N
J18: TK24077 | K18: Renewal | L18: Send Renewal Notice | M18: Bella Vista | N18: 2727254 | O18: 45664 | Q18: Simon | R18: Completed | T18: Y | U18: Annually
J19: TK24076 | K19: Reminder | L19: Send Reminder | M19: Deep Divers | N19: 2815655 | O19: 45661 | Q19: Simon | R19: Completed | T19: Y | U19: Annually
J20: TK24075 | K20: Meeting | L20: Life Proposal | M20: Sam Anadro | N20: 2711090 | O20: 45651 | Q20: Simon | R20: Completed | T20: N

Sheet LTO
A1: `
E2: Tasks - Overdue
E4: Records Found - 2
F6: Action | G6: Task ID | H6: Category | I6: Item | J6: Name | K6: Contact No | L6: Due Date | M6: Time | N6: Due in | O6: Assignee | P6: Task Status | Q6: Done Date | R6: Repeat | S6: Frequency | V6: Rpt Stop Date
G7: TK24081 | H7: Report | I7: Bi Annuall CFT Report | J7: FSA | K7: 4378645 | L7: =TODAY()-3 -> 45949 | N7: =L7-TODAY() -> -3 | O7: Simon | P7: Not Done | R7: Y | S7: Bi Annually
G8: TK24080 | H8: To Do | I8: Tax Return | J8: Seychelles Revenue Commission | K8: 4287555 | L8: =TODAY()-1 -> 45951 | N8: =L8-TODAY() -> -1 | O8: Simon | P8: In Progress | R8: Y | S8: Annually

Sheet DT
A1: `
E2: Tasks
E4: Records Found - 5
F6: Action | G6: Task ID | H6: Task ID | I6: Task ID | J6: Category | K6: Item | L6: Name | M6: Contact No | N6: Due Date | O6: Time | P6: Due in | Q6: Assignee | R6: Task Status | S6: Date Done | T6: Repeat | U6: Frequency | X6: Rpt Date | Y6: Rpt Stop Date
I7: TK24085 | J7: Event | K7: Presentation | L7: Hunt Deltel | M7: 4232323 | N7: =TODAY() -> 45952 | O7: 1600 | P7: 12 | Q7: Mandy | R7: Not Done | T7: N | X7: 45701
I8: TK24084 | J8: Payment | K8: PI Insurance Renewal | L8: Alliance | M8: 4223434 | N8: 45733 | P8: 7 | Q8: Mandy | R8: Not Done | T8: Y | U8: Annually | X8: 45699
I9: TK24083 | J9: Payment | K9: Annual Registration Fee | L9: Registrar Of Companies | M9: 2711511 | N9: 45730 | P9: 13 | Q9: Mandy | R9: Not Done | T9: Y | U9: Annually | X9: 45695
I10: TK24082 | J10: Report | K10: Financial Audit Report | L10: FSA | M10: 4378645 | N10: 45727 | P10: 1 | Q10: Simon | R10: Not Done | T10: Y | U10: Annually
I11: TK24081 | J11: Report | K11: Bi Annuall CFT Report | L11: FSA | M11: 4378645 | N11: 45726 | P11: 14 | Q11: Simon | R11: Not Done | T11: Y | U11: Bi Annually | X11: 45694
X12: 45691
X13: 45688
X14: 45687
X15: 45685
X16: 45672
X18: 45664
X19: 45661

Sheet LFU
A1: `
E2: Follow Ups
E4: Records 1 to 15 of 24
F6: Action | G6: FUID | H6: FUID | I6: FUID | J6: Due Date | K6: Due in | L6: Category | M6: Name | N6: Follow Up Note | O6: Contact No | P6: Policy No | Q6: FU Status | R6: Date Done | S6: Comment
I7: FU25033 | J7: 45278 | K7: =J7-TODAY() -> -674 | L7: Proposal | M7: Thomas Burns | N7: Follow Up On Offer | O7: 2765997 | Q7: Not Done | R7: 45730
I8: FU25032 | J8: =TODAY()+36 -> 45988 | K8: =J8-TODAY() -> 36 | L8: Proposal | M8: Oscar Medin | N8: Follow Up On Offer | O8: 2713397 | P8: PL-030-1-0000231 | Q8: Not Done | R8: 45762
I9: FU25031 | J9: =TODAY()+8 -> 45960 | K9: =J9-TODAY() -> 8 | L9: Proposal | M9: Sierra Fox | O9: 4378645 | P9: MTP-23-HEA-P0000321 | Q9: Not Done | R9: 45734
I10: FU25030 | J10: 45608 | K10: 12 | L10: Proposal | M10: Wayne Costa | N10: Sony Cosya's ID | O10: 2545412 | Q10: Not Done | R10: 45608
I11: FU25029 | J11: =TODAY()+17 -> 45969 | K11: =J11-TODAY() -> 17 | L11: Contact | M11: Autocars (Pty) Ltd | N11: Company registration documents | O11: 4223434 | Q11: Not Done | R11: 45743
I12: FU25028 | J12: =TODAY()+28 -> 45980 | K12: =J12-TODAY() -> 28 | L12: Contact | M12: Trevor Kanot | N12: To start life policy | O12: 2711511 | Q12: Not Done | R12: 45754
I13: FU25027 | J13: =TODAY()+32 -> 45984 | K13: =J13-TODAY() -> 32 | L13: Contact | M13: Ted David | N13: Confirm meeting | O13: 2643234 | Q13: Not Done | R13: 45758
I14: FU25026 | J14: =TODAY()+32 -> 45984 | K14: =J14-TODAY() -> 32 | L14: Contact | M14: Monica Bird | N14: When to meet | O14: 2711511 | Q14: Not Done | R14: 45758
I15: FU25025 | J15: =TODAY()+34 -> 45986 | K15: =J15-TODAY() -> 34 | L15: Contact | M15: Peter Cox | N15: Awaiting Deposit | O15: 4223456 | Q15: Not Done | R15: 45760
I16: FU25024 | J16: =TODAY()+32 -> 45984 | K16: =J16-TODAY() -> 32 | L16: Contact | M16: George Bash | N16: Awaiting Deposit | O16: 2514231 | Q16: FU25031 | R16: FU25028
I17: FU25023 | J17: =TODAY()+34 -> 45986 | K17: =J17-TODAY() -> 34 | L17: Contact | M17: Shana Green | N17: Awaiting Document | O17: 2643234 | Q17: Not Done | R17: 45765
I18: FU25022 | J18: =TODAY()+32 -> 45984 | K18: =J18-TODAY() -> 32 | L18: Contact | M18: Keystone Brokers(Pty) Ltd | O18: 2717171 | Q18: Not Done | R18: 45766
I19: FU25021 | J19: =TODAY()+41 -> 45993 | K19: =J19-TODAY() -> 41 | L19: Contact | M19: Walton Wild | O19: 4223456 | Q19: Not Done | R19: 45767
I20: FU25020 | J20: =TODAY()+42 -> 45994 | K20: =J20-TODAY() -> 42 | L20: Contact | M20: William Scott | O20: 2514231 | P20: PL-030-1-0094837 | Q20: Not Done | R20: 45768

Sheet PFU
E2: Contacts - To Follow Up
E4: Records Found - 11
F6: Action | G6: Contact Name | H6: Contact No | I6: Type | J6: Source | K6: Acquired | L6: Status | M6: 1st Called | N6: Rank | O6: 2FU | P6: Next FU | R6: Occupation | U6: Status | V6: Employer | W6: Agency | X6: Address | Y6: Contact ID | Z6: Savings Budget | AA6: Married | AB6: Children | AC6: Children Details | AD6: Vehicle | AE6: House | AF6: Business | AG6: Other | AH6: Source Name
G7: Wanda Lucas | H7: 4423212 | I7: Prospect | J7: Referal | K7: 45778 | L7: Proposal Made | M7: 45781 | N7: Warm | O7: Y | P7: 45393 | R7: Driver | U7: Active | V7: SEYPEC | W7: Keystone | X7: Beau Vallon | Y7: LD24-0077
G8: Debra Grey | H8: 2511611 | I8: Lead | J8: Direct | K8: 45778 | L8: Not Contacted | N8: Hot | R8: Accountant | U8: Active | V8: Cable & Wireless | W8: Keystone | X8: Mont Fleuri | Y8: LD24-0076 | AH8: Blake Seven
G9: Sheila Ewang | H9: 2765432 | I9: Lead | J9: Referal | K9: =TODAY()-3 -> 45949 | L9: Qualified | M9: 45453 | N9: Warm | O9: Y | P9: 45325 | R9: Customer Service Officer | U9: Active | V9: AIRTEL | W9: Keystone | X9: Beau Vallon | Y9: LD24-0075 | AH9: Yvon Coburn
G10: Kirk Patrick | H10: 4373234 | I10: Lead | J10: Walk In | K10: 45711 | L10: In Discussion | M10: 45432 | N10: Warm | O10: Y | P10: 45432 | R10: Contractor | U10: Active | W10: Keystone | X10: Cascade | Y10: LD24-0074
G11: Scott Svenson | H11: 4378645 | I11: Lead | J11: Referal | K11: 45709 | L11: Keep In View | M11: 45387 | N11: Cool | O11: Y | P11: 42908 | R11: Technician | U11: In Active | W11: Keystone | X11: Victoria | Y11: LD24-0073 | AH11: Kim Walton
G12: Samuel Hill | H12: 2514231 | I12: Lead | J12: Referal | K12: 45704 | L12: In Discussion | M12: 45440 | N12: Warm | O12: Y | P12: 45446 | R12: Payroll Officier | U12: Active | V12: SPTC | X12: Mont Fleuri | Y12: LD24-0073 | AH12: Samantha Dopilo
G13: Kaste McEwan | H13: 2765887 | I13: Prospect | J13: Referal | K13: 45691 | L13: Proposal Made | M13: 45439 | N13: Warm | O13: Y | P13: 45427 | R13: Boat Charter | U13: Active | V13: Inter Island Boats | W13: Keystone | X13: Beau Vallon | Y13: LD24-0072 | AH13: Trevor Crusher
G14: Mary Trader | H14: 4373234 | I14: Prospect | J14: Walk In | K14: 45684 | L14: Proposal Made | M14: 45432 | N14: Warm | O14: Y | P14: 45432 | R14: Contractor | U14: Active | W14: Keystone | X14: Providence | Y14: LD24-0071
G15: Damien Kinmo | H15: 2787653 | I15: Lead | J15: Direct | K15: 45680 | L15: Differed | M15: 30602 | N15: Warm | O15: Y | P15: 45943 | R15: Human Resources Manager | U15: Active | W15: Keystone | X15: Grand Anse | Y15: LD24-0070
G16: Dua Gomez | H16: 4378645 | I16: Lead | J16: Referal | K16: 45556 | L16: Open | M16: 45387 | N16: KIV | O16: Y | P16: 42908 | R16: Technician | U16: Active | V16: SPTC | X16: Mont Fleuri | Y16: LD24-0073 | AH16: Kim Walton
G17: Cox Santana | H17: 4378677 | I17: Lead | J17: Referal | K17: =TODAY()-44 -> 45908 | L17: Open | M17: 45387 | N17: Warm | O17: Y | P17: 42908 | R17: Technician | U17: Active | V17: Inter Island Boats | W17: Keystone | X17: Beau Vallon | Y17: LD24-0072 | AH17: Barry Marks
U18: Active | W18: Keystone | X18: Providence | Y18: LD24-0071
U19: Active | W19: Keystone | X19: Grand Anse | Y19: LD24-0070
U20: Active | W20: Keystone | X20: Anse Aux Pins | Y20: LD24-0069
U21: Active | W21: Keystone | X21: Grand Anse | Y21: LD24-0070

Sheet LFUD
A1: `
E2: Follow Ups
E4: Records 1 to 15 of 24
J6: FUID | K6: Name | L6: Contact No | M6: Policy No | N6: Category | O6: Due Date | P6: Due in | Q6: Follow Up Note | R6: FU Status | S6: Date Done
J7: FU25033 | K7: Keven Minion | L7: 2765997 | M7: MPV-23-PRO-P0003452 | N7: Reminder | O7: =TODAY()+4 -> 45956 | P7: =O7-TODAY() -> 4 | Q7: Renewal Reminder | R7: Not Done | S7: 45730
J8: FU25032 | K8: Oscar Medin | L8: 2713397 | M8: PL-030-1-0000231 | N8: Reminder | O8: =TODAY()+36 -> 45988 | P8: =O8-TODAY() -> 36 | Q8: Renewal Reminder | R8: Not Done | S8: 45762
J9: FU25031 | K9: Sierra Fox | L9: 4378645 | M9: MTP-23-HEA-P0000321 | N9: Reminder | O9: =TODAY()+8 -> 45960 | P9: =O9-TODAY() -> 8 | Q9: Renewal Reminder | R9: Not Done | S9: 45734
J10: FU25030 | K10: Wayne Costa | L10: 2545412 | N10: Reminder | O10: 45608 | P10: 12 | Q10: Sony Cosya's ID | R10: Not Done | S10: 45608
J11: FU25029 | K11: Autocars (Pty) Ltd | L11: 4223434 | N11: Reminder | O11: =TODAY()+17 -> 45969 | P11: =O11-TODAY() -> 17 | Q11: Company registration documents | R11: Not Done | S11: 45743
J12: FU25028 | K12: Trevor Kanot | L12: 2711511 | N12: To Do | O12: =TODAY()+28 -> 45980 | P12: =O12-TODAY() -> 28 | Q12: To start life policy | R12: Not Done | S12: 45754
J13: FU25027 | K13: Ted David | L13: 2643234 | N13: Discussion | O13: =TODAY()+32 -> 45984 | P13: =O13-TODAY() -> 32 | Q13: Confirm meeting | R13: Not Done | S13: 45758
J14: FU25026 | K14: Monica Bird | L14: 2711511 | N14: Discussion | O14: =TODAY()+32 -> 45984 | P14: =O14-TODAY() -> 32 | Q14: When to meet | R14: Not Done | S14: 45758
J15: FU25025 | K15: Peter Cox | L15: 4223456 | N15: Follow up | O15: =TODAY()+34 -> 45986 | P15: =O15-TODAY() -> 34 | Q15: Ready to start Life policy | R15: Not Done | S15: 45760
J16: FU25024 | K16: George Bash | L16: 2514231 | N16: Follow up | O16: =TODAY()+32 -> 45984 | P16: =O16-TODAY() -> 32 | Q16: Ready for 1st deposit | R16: FU25031 | S16: FU25028
J17: FU25023 | K17: Shana Green | L17: 2643234 | N17: Follow up | O17: =TODAY()+34 -> 45986 | P17: =O17-TODAY() -> 34 | R17: Not Done | S17: 45765
J18: FU25022 | K18: Keystone Brokers(Pty) Ltd | L18: 2717171 | N18: To Do | O18: =TODAY()+32 -> 45984 | P18: =O18-TODAY() -> 32 | R18: Not Done | S18: 45766
J19: FU25021 | K19: Walton Wild | L19: 4223456 | N19: Report | O19: =TODAY()+41 -> 45993 | P19: =O19-TODAY() -> 41 | R19: Not Done | S19: 45767
J20: FU25020 | K20: William Scott | L20: 2514231 | M20: PL-030-1-0094837 | N20: Reminder | O20: =TODAY()+42 -> 45994 | P20: =O20-TODAY() -> 42 | R20: Not Done | S20: 45768

Sheet AFU
E2: Follow Ups
E4: Records 1 to 15 of 143
J6: Task ID | K6: Task Type | L6: Due Date | M6: Due in | N6: Task Note | O6: Task Status | P6: Repeat | Q6: Policy No | R6: Contact | S6: Contact No
J7: TK24088 | K7: Renewal | L7: =TODAY()+4 -> 45956 | M7: =L7-TODAY() -> 4 | N7: S4396 | O7: Not Done | P7: Y | Q7: MPV-23-HEA-P003453 | R7: Adbul Jumaye | S7: 2765997
J8: TK24087 | K8: Renewal Notice | L8: =TODAY()+6 -> 45958 | M8: =L8-TODAY() -> 6 | O8: Sent by SMS | P8: Y | Q8: MPV-23-HEA-P0002132 | R8: Jean Grey | S8: 4373234
J9: TK24086 | K9: Reminder | L9: =TODAY()+8 -> 45960 | M9: =L9-TODAY() -> 8 | O9: Sent to Wattsapp | P9: Y | Q9: MTP-23-HEA-P0000321 | R9: Agricultural Corporative | S9: 4378645
J10: TK24085 | K10: Presentation | L10: =TODAY()+12 -> 45964 | M10: =L10-TODAY() -> 12 | N10: 10am at Hunt Deltel | O10: Booked
J11: TK24084 | K11: Follow Up | L11: =TODAY()+17 -> 45969 | M11: =L11-TODAY() -> 17 | O11: SMS Reminder Sent | P11: Y | Q11: PLI-23-P00023432 | R11: Autocars (Pty) Ltd | S11: 4223434
J12: TK24083 | K12: To Do | L12: =TODAY()+28 -> 45980 | M12: =L12-TODAY() -> 28 | N12: Broker Lisence | O12: Not Done | P12: Y | R12: Keystone Broker (Pty) Ltd | S12: 2711511
J13: TK24082 | K13: Renewal Notice | L13: =TODAY()+32 -> 45984 | M13: =L13-TODAY() -> 32 | O13: Not Done | P13: Y | Q13: CAR-PL-003234 | R13: Tween David | S13: 2643234
J14: TK24081 | K14: To Do | L14: =TODAY()+32 -> 45984 | M14: =L14-TODAY() -> 32 | N14: Annual Registration Fee | O14: Not Done | P14: Y | R14: Keystone Brokers(Pty) Ltd | S14: 2717171
J15: TK24080 | K15: To Do | L15: =TODAY()+34 -> 45986 | M15: =L15-TODAY() -> 34 | N15: Bi Annual CCF Report | O15: Not Done | P15: Y | R15: FSA | S15: 4223456
J16: TK24079 | K16: Reminder | L16: =TODAY()+36 -> 45988 | M16: =L16-TODAY() -> 36 | O16: Not Done | P16: Y | Q16: PL-030-1-0000231 | R16: Oscar Medin | S16: 2514231
J17: TK24078 | K17: Renewal Notice | L17: =TODAY()+39 -> 45991 | M17: =L17-TODAY() -> 39 | O17: Not Done | P17: Y | Q17: CAR-PL-003234 | R17: Shana Green | S17: 2643234
J18: TK24077 | K18: To Do | L18: =TODAY()+40 -> 45992 | M18: =L18-TODAY() -> 40 | O18: Not Done | P18: Y | R18: Keystone Brokers(Pty) Ltd | S18: 2717171
J19: TK24076 | K19: Report | L19: =TODAY()+41 -> 45993 | M19: =L19-TODAY() -> 41 | O19: Not Done | P19: Y | R19: Walton Wild | S19: 4223456
J20: TK24075 | K20: Reminder | L20: =TODAY()+42 -> 45994 | M20: =L20-TODAY() -> 42 | O20: Not Done | Q20: PL-030-1-0094837 | R20: William Scott | S20: 2514231

Sheet DFR
E2: Policies Due For Renewal
E4: Records Found - 5
F6: Action | G6: Policy No | H6: End Date | I6: Due In | J6: Status | K6: Client Name | L6: Insurer | M6: Policy Class | N6: Policy Plan | O6: Item | P6: Premium
G7: MPV-23-PRO-P000231 | H7: =TODAY()-2 -> 45950 | I7: =H7-TODAY() -> -2 | J7: Expired | K7: Lindsey Blake | L7: SACOS | M7: Motor | N7: Comprehensive | O7: S44444 | P7: 11455.893
G8: FSP-18-00010-P73422 | H8: =TODAY()+7 -> 45959 | I8: =H8-TODAY() -> 7 | J8: DFR | K8: Island Hideaway | L8: Hsavy | M8: General | N8: House Insurance | O8: House at Beau Vallon | P8: =T8*1.16 -> 0
G9: HS1-070-1-0029321 | H9: =TODAY()+10 -> 45962 | I9: =H9-TODAY() -> 10 | J9: DFR | K9: Island Hideaway | L9: Alliance | M9: General | N9: Public Liability | P9: =T9*1.16 -> 0
G10: HS1-070-1-0318323 | H10: =H9 -> 45962 | I10: =H10-TODAY() -> 10 | J10: DFR | K10: Island Hideaway | L10: Alliance | M10: General | N10: Employer's Liabilithy | P10: 2900
G11: FFA-00-HEA-P92322 | H11: =TODAY()+23 -> 45975 | I11: =H11-TODAY() -> 23 | J11: DFR | K11: The Lodge | L11: SACOS | M11: General | N11: Fire & Special Perils | O11: Guest House at Sans Soucis | P11: 27034

Sheet LID
E2: Premium Instalments Due
E4: Records Found - 5
